Error in <TNetXNGFile::Open>: [ERROR] Server responded with an error: [3010] permission denied

Error in <TNetXNGFile::Open>: [ERROR] Server responded with an error: [3010] permission denied

Error in <TNetXNGFile::Open>: [ERROR] Server responded with an error: [3010] permission denied

Error in <TNetXNGFile::Open>: [ERROR] Server responded with an error: [3010] permission denied

Error in <TNetXNGFile::Open>: [ERROR] Server responded with an error: [3010] permission denied

Error in <TNetXNGFile::Open>: [ERROR] Server responded with an error: [3010] permission denied

Error in <TNetXNGFile::Open>: [ERROR] Server responded with an error: [3010] permission denied

Error in <TNetXNGFile::Open>: [ERROR] Server responded with an error: [3010] permission denied

Error in <TNetXNGFile::Open>: [ERROR] Server responded with an error: [3010] permission denied

Error in <TNetXNGFile::Open>: [ERROR] Server responded with an error: [3010] permission denied

Error in <TNetXNGFile::Open>: [ERROR] Server responded with an error: [3010] permission denied

Error in <TNetXNGFile::Open>: [ERROR] Server responded with an error: [3010] permission denied

Error in <TNetXNGFile::Open>: [ERROR] Server responded with an error: [3010] permission denied

Error in <TNetXNGFile::Open>: [ERROR] Server responded with an error: [3010] permission denied

TClass::Init:0: RuntimeWarning: no dictionary for class edm::Hash<1> is available
TClass::Init:0: RuntimeWarning: no dictionary for class edm::ProcessHistory is available
TClass::Init:0: RuntimeWarning: no dictionary for class edm::ProcessConfiguration is available
TClass::Init:0: RuntimeWarning: no dictionary for class edm::ParameterSetBlob is available
TClass::Init:0: RuntimeWarning: no dictionary for class pair<edm::Hash<1>,edm::ParameterSetBlob> is available
TTreeReader::SetEntryBase():0: RuntimeWarning: There was an issue opening the last file associated to the TChain being processed.
Traceback (most recent call last):
  File "/afs/cern.ch/work/v/vdamante/public/analysis/triggerStudiesAnalysis.py", line 1474, in <module>
    path_perf_withEff2 = [(p[0], p[1].GetValue()/N_orig.GetValue(), math.sqrt(p[1].GetValue())/N_orig.GetValue()) for p in path_perf]
  File "/afs/cern.ch/work/v/vdamante/public/analysis/triggerStudiesAnalysis.py", line 1474, in <listcomp>
    path_perf_withEff2 = [(p[0], p[1].GetValue()/N_orig.GetValue(), math.sqrt(p[1].GetValue())/N_orig.GetValue()) for p in path_perf]
cppyy.gbl.std.runtime_error: const double& ROOT::RDF::RResultPtr<double>::GetValue() =>
    runtime_error: An error was encountered while processing the data. TTreeReader status code is: 5
